Workbook

Sheet Feb 13-17 Storm Summary Table
A1: Site | B1: Peak Level (ft) | C1: Total Rainfall (in)1 | D1: Rainfall Start Time2 | E1: Rainfall Stop Time2 | F1: Peak Time | H1: Staff gauge
A2: Del Dios | B2: =MAX('Del Dios Creek'!$C$3:$C$1239) -> 3.075 | C2: =SUM('Rainfall Data'!B$16:B$19) -> 3.46 | D2: ='Rainfall Duration Estimates'!C3 -> 43509.567 | E2: ='Rainfall Duration Estimates'!C4 -> 43513.748 | F2: 43510.559 | H2: 6 ft
A3: Felicita | B3: =MAX(Felicita!$C$224:$C$1249) -> 3.179 | C3: =SUM('Rainfall Data'!C$16:C$19) -> 3.32 | D3: 43509.567 | E3: 43513.748 | F3: 43510.601 | H3: 6 ft
A4: Moonsong | B4: =MAX(Moonsong!$E$191:$E$1239) -> 3.2570278 | C4: =SUM('Rainfall Data'!D$16:D$19) -> 3.36 | D4: 43509.567 | E4: 43513.748 | F4: 43510.58 | H4: 6 ft
A5: Green Valley | B5: =MAX('Green Valley'!$E$3:$E$1249) -> 4.8426667 | C5: =SUM('Rainfall Data'!E$16:E$19) -> 3.36 | D5: 43509.567 | E5: 43513.748 | F5: 43510.58 | H5: 8 ft
A6: Sycamore | B6: =MAX('Sycamore Creek'!$C$3:$C$1395) -> 5.123 | C6: =SUM('Rainfall Data'!F$16:F$19) -> 3.25 | D6: 43509.567 | E6: 43513.748 | F6: 43510.885 | H6: 8 ft
A7: Kit Carson | B7: =MAX('Kit Carson Creek'!$E$3:$E$1257) -> 3.8493333 | C7: =SUM('Rainfall Data'!G$16:G$19) -> 3.32 | D7: 43509.567 | E7: 43513.748 | F7: 43510.615 | H7: 8 ft
A8: Cloverdale | B8: =MAX(Cloverdale!$C$3:$C$1251) -> 3.463 | C8: =SUM('Rainfall Data'!H$16:H$19) -> 3.19 | D8: ='Rainfall Duration Estimates'!E3 -> 43509.558 | E8: ='Rainfall Duration Estimates'!E4 -> 43513.741 | F8: 43511.208 | H8: 6 ft
A9: Guejito | B9: =MAX('Guejito Creek'!$F$251:$F$1251) -> 5.998 | C9: =SUM('Rainfall Data'!I$16:I$19) -> 3.46 | D9: 43509.558 | E9: 43513.741 | F9: 43510.635 | H9: 8 ft
A11: 1. Precipitation records obtained from PRISM Data Group at http://www.prism.oregonstate.edu/explorer/
A12: 2. Start at stop times for rainfall are approximate and were obtained from OneRain where available (see tabs Rainfall Data and Rainfall Duration Estimates).

Sheet Feb 18 Storm Summary Table
A1: Site | B1: Peak Level (ft) | C1: Total Rainfall (in)1 | D1: Rainfall Start Time2 | E1: Rainfall Stop Time2 | F1: Peak Time
A2: Del Dios3,4 | B2: =MAX('Del Dios Creek'!$C$1239:$C$1825) -> 0.361 | C2: =SUM('Rainfall Data'!B$20:B$21) -> 0.33 | D2: ='Rainfall Duration Estimates'!C6 -> 43514.737 | E2: ='Rainfall Duration Estimates'!C7 -> 43514.763 | F2: 43513.75
A3: Felicita3 | B3: =MAX(Felicita!$C$1249:$C$1827) -> 0.924 | C3: =SUM('Rainfall Data'!C$20:C$21) -> 0.32 | D3: 43514.737 | E3: 43514.763 | F3: 43514.861
A4: Moonsong3 | B4: =MAX(Moonsong!$E$1239:$E$1815) -> 1.4270278 | C4: =SUM('Rainfall Data'!D$20:D$21) -> 0.38 | D4: 43514.737 | E4: 43514.763 | F4: 43514.816
A5: Green Valley3,4 | B5: =MAX('Green Valley'!$E$1249:$E$1825) -> 0.78766667 | C5: =SUM('Rainfall Data'!E$20:E$21) -> 0.38 | D5: 43514.737 | E5: 43514.763 | F5: 43513.753
A6: Sycamore4 | B6: =MAX('Sycamore Creek'!$C$1395:$C$1827) -> 0.653 | C6: =SUM('Rainfall Data'!F$20:F$21) -> 0.37 | D6: 43514.737 | E6: 43514.763 | F6: 43513.83
A7: Kit Carson3 | B7: =MAX('Kit Carson Creek'!$E$1257:$E$1827) -> 0.96933333 | C7: =SUM('Rainfall Data'!G$20:G$21) -> 0.32 | D7: 43514.737 | E7: 43514.763 | F7: 43514.771
A8: Cloverdale3,5 | B8: - 5 | C8: =SUM('Rainfall Data'!H$20:H$21) -> 0.32 | D8: ='Rainfall Duration Estimates'!E6 -> 43514.555 | E8: ='Rainfall Duration Estimates'!E7 -> 43514.753 | F8: - 5
A9: Guejito4 | B9: =MAX('Guejito Creek'!$F$1251:$F$1827) -> 0.308 | C9: =SUM('Rainfall Data'!I$20:I$21) -> 0.32 | D9: 43514.555 | E9: 43514.753 | F9: 43514.198
A11: 1. Precipitation records obtained from PRISM Data Group at http://www.prism.oregonstate.edu/explorer/
A12: 2. Start at stop times for rainfall are approximate and were obtained from OneRain where available (see tabs Rainfall Data and Rainfall Duration Estimates).
A13: 3. Judging from the level hydrograph, the site did not return to baseflow prior to the apparent start of rainfall for this storm. Observed level data is not representative of the watershed response for a storm of this size. Further data processing is required to use this data point in rating curve development.
A17: 4. Peak level occurs prior to apparent start of rainfall on nearest available rain gauge (Escondido). Recommend not using this storm for rating curve development.
A18: 5. Hydrograph recession of the first storm essentially supressed any apparent watershed response at this site during the second storm.

Sheet Feb 20 - 21 Storm Summary Table
A1: Site | B1: Peak Level (ft) | C1: Total Rainfall (in)1 | D1: Rainfall Start Time2 | E1: Rainfall Stop Time2 | F1: Peak Time
A2: Del Dios3 | B2: =MAX('Del Dios Creek'!$D$2231:$D$2867,'Del Dios Creek'!$E$2868:$E$4241) -> 0.602 | C2: =SUM('Rainfall Data'!B$23:B$24) -> 0.59 | D2: ='Rainfall Duration Estimates'!C9 -> 43516.586 | E2: ='Rainfall Duration Estimates'!C10 -> 43517.748 | F2: 43516.948
A3: Felicita3 | B3: =MAX(Felicita!$C$1827:$C$2247, Felicita!$D$2248:$D$4259) -> 1.144 | C3: =SUM('Rainfall Data'!C$23:C$24) -> 0.59 | D3: 43516.586 | E3: 43517.748 | F3: 43516.972
A4: Moonsong3 | B4: =MAX(Moonsong!$E$1815:$E$4260) -> 1.3930278 | C4: =SUM('Rainfall Data'!D$23:D$24) -> 0.76 | D4: 43516.586 | E4: 43517.748 | F4: 43517.483
A5: Green Valley3 | B5: =MAX('Green Valley'!$E$1825:$E$4252) -> 0.91566667 | C5: =SUM('Rainfall Data'!E$23:E$24) -> 0.76 | D5: 43516.586 | E5: 43517.748 | F5: 43517.493
A6: Sycamore | B6: =MAX('Sycamore Creek'!$C$1827:$C$4280) -> 1.787 | C6: =SUM('Rainfall Data'!F$23:F$24) -> 0.78 | D6: 43516.586 | E6: 43517.748 | F6: 43518.476
A7: Kit Carson3 | B7: =MAX('Kit Carson Creek'!$E$1827:$E$4336) -> 0.91333333 | C7: =SUM('Rainfall Data'!G$23:G$24) -> 0.59 | D7: 43516.586 | E7: 43517.748 | F7: 43517.073
A8: Cloverdale3 | B8: =MAX(Cloverdale!$C$1827:$C$4329) -> 1.387 | C8: =SUM('Rainfall Data'!H$23:H$24) -> 0.69 | D8: ='Rainfall Duration Estimates'!E9 -> 43516.574 | E8: ='Rainfall Duration Estimates'!E10 -> 43517.755 | F8: 43518.708
A9: Guejito | B9: =MAX('Guejito Creek'!$F$1827:$F$4291) -> 0.602 | C9: =SUM('Rainfall Data'!I$23:I$24) -> 0.8 | D9: 43516.574 | E9: 43517.755 | F9: 43517.608
A11: 1. Precipitation records obtained from PRISM Data Group at http://www.prism.oregonstate.edu/explorer/
A12: 2. Start at stop times for rainfall are approximate and were obtained from OneRain where available (see tabs Rainfall Data and Rainfall Duration Estimates).
A13: 3. Judging from the level hydrograph, the site did not return to baseflow prior to the start of rainfall for this storm. Observed level data is not representative of the watershed response for a storm of this size. Further data processing is required to use this data point in rating curve development.

Sheet Rainfall Data
B1: PRISM Rainfall Depth (in) | M1: OneRain Lake Hodges Rainfall Depth | T1: OneRain Santa Ysabel Rainfall Depth | Z1: OneRain Escondido Rainfall Depth
A2: Date | B2: Del Dios Creek | C2: Felicita Creek | D2: Moonsong Creek | E2: Green Valley Creek | F2: Sycamore Creek | G2: Kit Carson Creek | H2: Cloverdale Creek | I2: Guejito Creek | M2: Reading | N2: Receive | O2: Value | P2: Unit | Q2: Data Quality | R2: Incremental Rain (in) | T2: Reading | U2: Receive | V2: Value | W2: Unit | X2: Data Quality | Z2: Reading | AA2: Receive | AB2: Value | AC2: Unit | AD2: Data Quality | AE2: Incremental Rain (in)
A3: 43497 | B3: 0.71 | C3: 0.7 | D3: 0.65 | E3: 0.65 | F3: 0.64 | G3: 0.7 | H3: 0.66 | I3: 0.66 | M3: 2019-02-01 08:36:29 | N3: 2019-02-01 08:36:48 | O3: 8.67 | P3: in | Q3: A | T3: 43497.43 | U3: 43497.43 | V3: 0 | W3: in | X3: A | Z3: 43497.317 | AA3: 43497.317 | AB3: 9.52 | AC3: in | AD3: A
A4: 43498 | B4: 0.06 | C4: 0.06 | D4: 0.05 | E4: 0.05 | F4: 0.05 | G4: 0.06 | H4: 0.05 | I4: 0.05 | K4: Storm 1 | M4: 2019-02-01 12:52:03 | N4: 2019-02-01 12:52:48 | O4: 8.68 | P4: in | Q4: A | R4: =O4-O3 -> 0.01 | T4: 43497.93 | U4: 43497.93 | V4: 0 | W4: in | X4: A | Z4: 43497.817 | AA4: 43497.817 | AB4: 9.52 | AC4: in | AD4: A | AE4: =AB4-AB3 -> 0
A5: 43499 | B5: 1.19 | C5: 1.18 | D5: 1.27 | E5: 1.27 | F5: 1.24 | G5: 1.18 | H5: 1.21 | I5: 1.26 | K5: Storm 2 | M5: 2019-02-01 20:36:29 | N5: 2019-02-01 20:36:48 | O5: 8.68 | P5: in | Q5: A | R5: =O5-O4 -> 0 | T5: 43497.98 | U5: 43497.98 | V5: 0.01 | W5: in | X5: A | Z5: 43498.003 | AA5: 43498.004 | AB5: 9.53 | AC5: in | AD5: A | AE5: =AB5-AB4 -> 0.01
A6: 43500 | B6: 0.16 | C6: 0.15 | D6: 0.15 | E6: 0.15 | F6: 0.14 | G6: 0.15 | H6: 0.15 | I6: 0.13 | K6: Storm 3 | M6: 2019-02-02 00:04:27 | N6: 2019-02-02 00:04:48 | O6: 8.69 | P6: in | Q6: A | R6: =O6-O5 -> 0.01 | T6: 43497.992 | U6: 43497.993 | V6: 0.01 | W6: in | X6: A | Z6: 43498.022 | AA6: 43498.022 | AB6: 9.54 | AC6: in | AD6: A | AE6: =AB6-AB5 -> 0.01
A7: 43501 | B7: 0.59 | C7: 0.58 | D7: 0.72 | E7: 0.72 | F7: 0.74 | G7: 0.58 | H7: 0.62 | I7: 0.77 | M7: 2019-02-02 00:35:24 | N7: 2019-02-02 00:36:48 | O7: 8.7 | P7: in | Q7: A | R7: =O7-O6 -> 0.01 | T7: 43498.007 | U7: 43498.008 | V7: 0.01 | W7: in | X7: A | Z7: 43498.033 | AA7: 43498.034 | AB7: 9.55 | AC7: in | AD7: A | AE7: =AB7-AB6 -> 0.01
A8: 43502 | B8: 0.23 | C8: 0.24 | D8: 0.22 | E8: 0.22 | F8: 0.21 | G8: 0.24 | H8: 0.22 | I8: 0.25 | M8: 2019-02-02 02:05:36 | N8: 2019-02-02 02:06:48 | O8: 8.71 | P8: in | Q8: A | R8: =O8-O7 -> 0.01 | T8: 43498.029 | U8: 43498.03 | V8: 0.01 | W8: in | X8: A | Z8: 43498.112 | AA8: 43498.113 | AB8: 9.56 | AC8: in | AD8: A | AE8: =AB8-AB7 -> 0.01
A9: 43503 | B9: 0 | C9: 0 | D9: 0 | E9: 0 | F9: 0 | G9: 0 | H9: 0 | I9: 0 | M9: 2019-02-02 02:53:24 | N9: 2019-02-02 02:54:48 | O9: 8.72 | P9: in | Q9: A | R9: =O9-O8 -> 0.01 | T9: 43498.053 | U9: 43498.054 | V9: 0.01 | W9: in | X9: A | Z9: 43498.166 | AA9: 43498.167 | AB9: 9.57 | AC9: in | AD9: A | AE9: =AB9-AB8 -> 0.01
A10: 43504 | B10: 0 | C10: 0 | D10: 0 | E10: 0 | F10: 0 | G10: 0 | H10: 0 | I10: 0 | M10: 2019-02-02 05:40:49 | N10: 2019-02-02 05:42:48 | O10: 8.73 | P10: in | Q10: A | R10: =O10-O9 -> 0.01 | T10: 43498.105 | U10: 43498.106 | V10: 0.01 | W10: in | X10: A | Z10: 43498.317 | AA10: 43498.317 | AB10: 9.57 | AC10: in | AD10: A | AE10: =AB10-AB9 -> 0
A11: 43505 | B11: 0 | C11: 0 | D11: 0 | E11: 0 | F11: 0 | G11: 0 | H11: 0 | I11: 0 | M11: 2019-02-02 08:36:29 | N11: 2019-02-02 08:36:48 | O11: 8.73 | P11: in | Q11: A | R11: =O11-O10 -> 0 | T11: 43498.141 | U11: 43498.143 | V11: 0.01 | W11: in | X11: A | Z11: 43498.449 | AA11: 43498.45 | AB11: 9.58 | AC11: in | AD11: A | AE11: =AB11-AB10 -> 0.01
A12: 43506 | B12: 0.01 | C12: 0 | D12: 0 | E12: 0 | F12: 0 | G12: 0 | H12: 0 | I12: 0 | M12: 2019-02-02 10:47:38 | N12: 2019-02-02 10:48:48 | O12: 8.74 | P12: in | Q12: A | R12: =O12-O11 -> 0.01 | T12: 43498.161 | U12: 43498.162 | V12: 0.01 | W12: in | X12: A | Z12: 43498.471 | AA12: 43498.472 | AB12: 9.59 | AC12: in | AD12: A | AE12: =AB12-AB11 -> 0.01
A13: 43507 | B13: 0.06 | C13: 0.06 | D13: 0.07 | E13: 0.07 | F13: 0.06 | G13: 0.06 | H13: 0.05 | I13: 0.04 | M13: 2019-02-02 11:16:30 | N13: 2019-02-02 11:18:48 | O13: 8.75 | P13: in | Q13: A | R13: =O13-O12 -> 0.01 | T13: 43498.43 | U13: 43498.43 | V13: 0 | W13: in | X13: A | Z13: 43498.539 | AA13: 43498.539 | AB13: 9.6 | AC13: in | AD13: A | AE13: =AB13-AB12 -> 0.01
A14: 43508 | B14: 0 | C14: 0 | D14: 0 | E14: 0 | F14: 0 | G14: 0 | H14: 0 | I14: 0 | M14: 2019-02-02 13:00:17 | N14: 2019-02-02 13:00:48 | O14: 8.76 | P14: in | Q14: A | R14: =O14-O13 -> 0.01 | T14: 43498.476 | U14: 43498.476 | V14: 0.01 | W14: in | X14: A | Z14: 43498.541 | AA14: 43498.542 | AB14: 9.61 | AC14: in | AD14: A | AE14: =AB14-AB13 -> 0.01
A15: 43509 | B15: 0 | C15: 0 | D15: 0 | E15: 0 | F15: 0 | G15: 0 | H15: 0 | I15: 0 | M15: 2019-02-02 13:19:22 | N15: 2019-02-02 13:21:01 | O15: 8.77 | P15: in | Q15: A | R15: =O15-O14 -> 0.01 | T15: 43498.489 | U15: 43498.49 | V15: 0.01 | W15: in | X15: A | Z15: 43498.545 | AA15: 43498.546 | AB15: 9.62 | AC15: in | AD15: A | AE15: =AB15-AB14 -> 0.01
A16: 43510 | B16: 1.34 | C16: 1.29 | D16: 1.32 | E16: 1.32 | F16: 1.26 | G16: 1.29 | H16: 1.26 | I16: 1.26 | M16: 2019-02-02 13:24:52 | N16: 2019-02-02 13:26:48 | O16: 8.78 | P16: in | Q16: A | R16: =O16-O15 -> 0.01 | T16: 43498.493 | U16: 43498.494 | V16: 0.01 | W16: in | X16: A | Z16: 43498.55 | AA16: 43498.552 | AB16: 9.63 | AC16: in | AD16: A | AE16: =AB16-AB15 -> 0.01
A17: 43511 | B17: 1.98 | C17: 1.88 | D17: 1.84 | E17: 1.84 | F17: 1.78 | G17: 1.88 | H17: 1.74 | I17: 1.99 | M17: 2019-02-02 13:31:29 | N17: 2019-02-02 13:32:48 | O17: 8.79 | P17: in | Q17: A | R17: =O17-O16 -> 0.01 | T17: 43498.536 | U17: 43498.537 | V17: 0.01 | W17: in | X17: A | Z17: 43498.555 | AA17: 43498.556 | AB17: 9.64 | AC17: in | AD17: A | AE17: =AB17-AB16 -> 0.01
A18: 43512 | B18: 0.13 | C18: 0.14 | D18: 0.18 | E18: 0.18 | F18: 0.19 | G18: 0.14 | H18: 0.17 | I18: 0.19 | M18: 2019-02-02 13:37:21 | N18: 2019-02-02 13:38:49 | O18: 8.8 | P18: in | Q18: A | R18: =O18-O17 -> 0.01 | T18: 43498.544 | U18: 43498.544 | V18: 0.01 | W18: in | X18: A | Z18: 43498.559 | AA18: 43498.56 | AB18: 9.65 | AC18: in | AD18: A | AE18: =AB18-AB17 -> 0.01
... A30: 43524 | B30: 0 | C30: 0 | D30: 0 | E30: 0 | F30: 0 | G30: 0 | H30: 0 | I30: 0 | M30: 2019-02-02 14:55:41 | N30: 2019-02-02 14:56:48 | O30: 8.92 | P30: in | Q30: A | R30: =O30-O29 -> 0.01 | T30: 43498.61 | U30: 43498.611 | V30: 0.01 | W30: in | X30: A | Z30: 43498.61 | AA30: 43498.611 | AB30: 9.77 | AC30: in | AD30: A | AE30: =AB30-AB29 -> 0.01
M31: 2019-02-02 15:01:14 | N31: 2019-02-02 15:02:49 | O31: 8.93 | P31: in | Q31: A | R31: =O31-O30 -> 0.01 | T31: 43498.614 | U31: 43498.615 | V31: 0.01 | W31: in | X31: A | Z31: 43498.62 | AA31: 43498.621 | AB31: 9.78 | AC31: in | AD31: A | AE31: =AB31-AB30 -> 0.01
M32: 2019-02-02 15:04:22 | N32: 2019-02-02 15:04:48 | O32: 8.94 | P32: in | Q32: A | R32: =O32-O31 -> 0.01 | T32: 43498.617 | U32: 43498.618 | V32: 0.01 | W32: in | X32: A | Z32: 43498.623 | AA32: 43498.624 | AB32: 9.79 | AC32: in | AD32: A | AE32: =AB32-AB31 -> 0.01
M33: 2019-02-02 15:09:00 | N33: 2019-02-02 15:10:49 | O33: 8.95 | P33: in | Q33: A | R33: =O33-O32 -> 0.01 | T33: 43498.62 | U33: 43498.62 | V33: 0.01 | W33: in | X33: A | Z33: 43498.631 | AA33: 43498.632 | AB33: 9.8 | AC33: in | AD33: A | AE33: =AB33-AB32 -> 0.01
M34: 2019-02-02 15:13:15 | N34: 2019-02-02 15:14:48 | O34: 8.96 | P34: in | Q34: A | R34: =O34-O33 -> 0.01 | T34: 43498.628 | U34: 43498.629 | V34: 0.01 | W34: in | X34: A | Z34: 43498.636 | AA34: 43498.638 | AB34: 9.81 | AC34: in | AD34: A | AE34: =AB34-AB33 -> 0.01
M35: 2019-02-02 15:15:15 | N35: 2019-02-02 15:16:49 | O35: 8.97 | P35: in | Q35: A | R35: =O35-O34 -> 0.01 | T35: 43498.639 | U35: 43498.64 | V35: 0.01 | W35: in | X35: A | Z35: 43498.638 | AA35: 43498.639 | AB35: 9.82 | AC35: in | AD35: A | AE35: =AB35-AB34 -> 0.01
M36: 2019-02-02 15:16:27 | N36: 2019-02-02 15:16:49 | O36: 8.98 | P36: in | Q36: A | R36: =O36-O35 -> 0.01 | T36: 43498.643 | U36: 43498.644 | V36: 0.01 | W36: in | X36: A | Z36: 43498.639 | AA36: 43498.64 | AB36: 9.83 | AC36: in | AD36: A | AE36: =AB36-AB35 -> 0.01
M37: 2019-02-02 15:17:41 | N37: 2019-02-02 15:18:49 | O37: 8.99 | P37: in | Q37: A | R37: =O37-O36 -> 0.01 | T37: 43498.646 | U37: 43498.647 | V37: 0.01 | W37: in | X37: A | Z37: 43498.64 | AA37: 43498.64 | AB37: 9.84 | AC37: in | AD37: A | AE37: =AB37-AB36 -> 0.01
M38: 2019-02-02 15:17:59 | N38: 2019-02-02 15:18:49 | O38: 9 | P38: in | Q38: A | R38: =O38-O37 -> 0.01 | T38: 43498.648 | U38: 43498.648 | V38: 0.01 | W38: in | X38: A | Z38: 43498.64 | AA38: 43498.64 | AB38: 9.85 | AC38: in | AD38: A | AE38: =AB38-AB37 -> 0.01
M39: 2019-02-02 15:18:11 | N39: 2019-02-02 15:18:49 | O39: 9.01 | P39: in | Q39: A | R39: =O39-O38 -> 0.01 | T39: 43498.65 | U39: 43498.651 | V39: 0.01 | W39: in | X39: A | Z39: 43498.64 | AA39: 43498.64 | AB39: 9.86 | AC39: in | AD39: A | AE39: =AB39-AB38 -> 0.01
M40: 2019-02-02 15:18:18 | N40: 2019-02-02 15:18:49 | O40: 9.02 | P40: in | Q40: A | R40: =O40-O39 -> 0.01 | T40: 43498.652 | U40: 43498.652 | V40: 0.01 | W40: in | X40: A | Z40: 43498.642 | AA40: 43498.643 | AB40: 9.87 | AC40: in | AD40: A | AE40: =AB40-AB39 -> 0.01
M41: 2019-02-02 15:18:31 | N41: 2019-02-02 15:20:49 | O41: 9.03 | P41: in | Q41: A | R41: =O41-O40 -> 0.01 | T41: 43498.653 | U41: 43498.654 | V41: 0.01 | W41: in | X41: A | Z41: 43498.643 | AA41: 43498.643 | AB41: 9.88 | AC41: in | AD41: A | AE41: =AB41-AB40 -> 0.01
M42: 2019-02-02 15:18:45 | N42: 2019-02-02 15:20:49 | O42: 9.04 | P42: in | Q42: A | R42: =O42-O41 -> 0.01 | T42: 43498.655 | U42: 43498.655 | V42: 0.01 | W42: in | X42: A | Z42: 43498.643 | AA42: 43498.643 | AB42: 9.89 | AC42: in | AD42: A | AE42: =AB42-AB41 -> 0.01
... M687: 2019-02-23 08:36:29 | N687: 2019-02-23 08:36:48 | O687: 15.27 | P687: in | Q687: A | R687: =O687-O686 -> 0 | T687: 43510.326 | U687: 43510.327 | V687: 0.01 | W687: in | X687: A | Z687: 43524.918 | AA687: 43524.918 | AB687: 15.84 | AC687: in | AD687: A | AE687: =AB687-AB686 -> 0
M688: 2019-02-23 20:36:29 | N688: 2019-02-23 20:36:48 | O688: 15.27 | P688: in | Q688: A | R688: =O688-O687 -> 0 | T688: 43510.327 | U688: 43510.327 | V688: 0.01 | W688: in | X688: A
M689: 2019-02-24 08:36:29 | N689: 2019-02-24 08:36:48 | O689: 15.27 | P689: in | Q689: A | R689: =O689-O688 -> 0 | T689: 43510.329 | U689: 43510.33 | V689: 0.01 | W689: in | X689: A
M690: 2019-02-24 20:36:29 | N690: 2019-02-24 20:36:48 | O690: 15.27 | P690: in | Q690: A | R690: =O690-O689 -> 0 | T690: 43510.331 | U690: 43510.331 | V690: 0.01 | W690: in | X690: A
M691: 2019-02-25 08:36:30 | N691: 2019-02-25 08:37:01 | O691: 15.27 | P691: in | Q691: A | R691: =O691-O690 -> 0 | T691: 43510.332 | U691: 43510.333 | V691: 0.01 | W691: in | X691: A
M692: 2019-02-25 20:36:29 | N692: 2019-02-25 20:36:48 | O692: 15.27 | P692: in | Q692: A | R692: =O692-O691 -> 0 | T692: 43510.332 | U692: 43510.333 | V692: 0.01 | W692: in | X692: A
M693: 2019-02-26 08:36:30 | N693: 2019-02-26 08:36:48 | O693: 15.27 | P693: in | Q693: A | R693: =O693-O692 -> 0 | T693: 43510.334 | U693: 43510.334 | V693: 0.01 | W693: in | X693: A
M694: 2019-02-26 20:36:29 | N694: 2019-02-26 20:36:57 | O694: 15.27 | P694: in | Q694: A | R694: =O694-O693 -> 0 | T694: 43510.334 | U694: 43510.336 | V694: 0.01 | W694: in | X694: A
M695: 2019-02-27 08:36:29 | N695: 2019-02-27 08:37:01 | O695: 15.27 | P695: in | Q695: A | R695: =O695-O694 -> 0 | T695: 43510.337 | U695: 43510.338 | V695: 0.01 | W695: in | X695: A
...

Sheet Rainfall Duration Estimates
C1: OneRain Rain Guage | H1: Latitude | I1: Longitude
C2: Lake Hodges | D2: Santa Ysabel | E2: Escondido | G2: Lake Hodges | H2: 33.066389 | I2: -117.10583
A3: Storm 1 | B3: Start | C3: 43509.567 | D3: 43509.57 | E3: 43509.558 | G3: Santa Ysabel | H3: 33.110246 | I3: -116.6733
B4: Stop | C4: 43513.748 | D4: 43513.908 | E4: 43513.741 | G4: Escondido | H4: 33.119722 | I4: -117.095
B5: Duration (hours) | C5: =(C4-C3)*24 -> 100.33833 | D5: =(D4-D3)*24 -> 104.11667 | E5: =(E4-E3)*24 -> 100.38333
A6: Storm 2 | B6: Start | C6: 43514.737 | D6: 43513.957 | E6: 43514.555 | G6: Del Dios | H6: 33.078051 | I6: -117.1156
B7: Stop | C7: 43514.763 | D7: 43514.156 | E7: 43514.753 | G7: Felicita | H7: 33.068984 | I7: -117.08052
B8: Duration (hours) | C8: =(C7-C6)*24 -> 0.63166667 | D8: =(D7-D6)*24 -> 4.7666667 | E8: =(E7-E6)*24 -> 4.75 | G8: Moonsong | H8: 33.044517 | I8: -117.08896
A9: Storm 3 | B9: Start | C9: 43516.586 | D9: 43516.588 | E9: 43516.574 | G9: Green Valley | H9: 33.049297 | I9: -117.07621
B10: Stop | C10: 43517.748 | D10: 43518.533 | E10: 43517.755 | G10: Sycamore | H10: 33.051659 | I10: -117.04441
B11: Duration (hours) | C11: =(C10-C9)*24 -> 27.901944 | D11: =(D10-D9)*24 -> 46.666667 | E11: =(E10-E9)*24 -> 28.35 | G11: Kit Carson | H11: 33.067853 | I11: -117.06607
G12: Cloverdale | H12: 33.091139 | I12: -117.01999
C13: Proximity to Monitoring Location (miles) | G13: Guejito | H13: 33.095456 | I13: -116.96146
C14: Lake Hodges | D14: Santa Ysabel | E14: Escondido
A15: Site | B15: Del Dios | C15: 0.98 | D15: 25.7 | E15: 3.12
B16: Felicita | C16: 1.48 | D16: 23.74 | E16: 3.6
B17: Moonsong | C17: 1.8 | D17: 24.49 | E17: 5.21
B18: Green Valley | C18: 2.08 | D18: 23.7 | E18: 4.99
B19: Sycamore | C19: 3.7 | D19: 21.86 | E19: 5.54
B20: Kit Carson | C20: 2.3 | D20: 22.92 | E20: 3.44
B21: Cloverdale | C21: 5.26 | D21: 20.11 | E21: 4.77
B22: Guejito | C22: 8.6 | D22: 14.52 | E22: 7.91

Sheet Del Dios Creek
A1: Plot Title: 13
A2: # | B2: Date Time, GMT-08:00 | C2: Water Level, feet
A3: 13 | B3: 43508.708 | C3: 0 | G3: 43508.708
A4: 14 | B4: 43508.712 | C4: 0.008 | G4: 43508.712
A5: 15 | B5: 43508.715 | C5: 0.006 | G5: 43508.715
A6: 16 | B6: 43508.719 | C6: 0.004 | G6: 43508.719
A7: 17 | B7: 43508.722 | C7: 0.006 | G7: 43508.722
A8: 18 | B8: 43508.726 | C8: 0.007 | G8: 43508.726
A9: 19 | B9: 43508.729 | C9: 0.003 | G9: 43508.729
A10: 20 | B10: 43508.733 | C10: 0.003 | G10: 43508.733
A11: 21 | B11: 43508.736 | C11: 0.006 | G11: 43508.736
A12: 22 | B12: 43508.74 | C12: 0.01 | G12: 43508.74
A13: 23 | B13: 43508.743 | C13: 0.003 | G13: 43508.743
A14: 24 | B14: 43508.747 | C14: -0.001 | G14: 43508.747
... A23: 33 | B23: 43508.778 | C23: 0 | G23: 43508.778
A24: 34 | B24: 43508.781 | C24: 0.003 | G24: 43508.781 | J24: Rain (in) | K24: Offset (in) | L24: Peak Level (in)
A25: 35 | B25: 43508.785 | C25: 0.007 | G25: 43508.785 | J25: ='Feb 13-17 Storm Summary Table'!C2 -> 3.46 | K25: 0 | L25: ='Feb 13-17 Storm Summary Table'!B2-K25 -> 3.075
A26: 36 | B26: 43508.788 | C26: 0.009 | G26: 43508.788 | J26: ='Feb 18 Storm Summary Table'!C2 -> 0.33 | K26: 0.188 | L26: ='Feb 18 Storm Summary Table'!B2-K26 -> 0.173
A27: 37 | B27: 43508.792 | C27: 0.006 | G27: 43508.792 | J27: ='Feb 20 - 21 Storm Summary Table'!C2 -> 0.59 | K27: 0.2 | L27: ='Feb 20 - 21 Storm Summary Table'!B2-K27 -> 0.402
A28: 38 | B28: 43508.795 | C28: 0.004 | G28: 43508.795
A29: 39 | B29: 43508.799 | C29: 0.006 | G29: 43508.799
A30: 40 | B30: 43508.802 | C30: 0.012 | G30: 43508.802
A31: 41 | B31: 43508.806 | C31: 0.006 | G31: 43508.806
A32: 42 | B32: 43508.809 | C32: 0.006 | G32: 43508.809
A33: 43 | B33: 43508.812 | C33: 0.003 | G33: 43508.812
A34: 44 | B34: 43508.816 | C34: -0.002 | G34: 43508.816
A35: 45 | B35: 43508.819 | C35: 0.003 | G35: 43508.819
A36: 46 | B36: 43508.823 | C36: 0.008 | G36: 43508.823
A37: 47 | B37: 43508.826 | C37: 0.005 | G37: 43508.826
A38: 48 | B38: 43508.83 | C38: 0.008 | G38: 43508.83
A39: 49 | B39: 43508.833 | C39: 0.005 | G39: 43508.833
... A2227: 2237 | B2227: 43516.431 | C2227: 0.073 | G2227: 43516.431
A2228: 2238 | B2228: 43516.431 | E2228: =C2231-C2226 -> 0.107 | G2228: 43516.431
A2229: 2239 | B2229: 43516.434 | G2229: 43516.434
A2230: 2240 | B2230: 43516.434 | C2230: 0.019 | G2230: 43516.434
A2231: 2241 | B2231: 43516.438 | C2231: 0.299 | D2231: =C2231-E$2228 -> 0.192 | G2231: 43516.438
A2232: 2242 | B2232: 43516.441 | C2232: 0.3 | D2232: =C2232-E$2228 -> 0.193 | G2232: 43516.441
A2233: 2243 | B2233: 43516.444 | C2233: 0.3 | D2233: =C2233-E$2228 -> 0.193 | G2233: 43516.444
A2234: 2244 | B2234: 43516.448 | C2234: 0.3 | D2234: =C2234-E$2228 -> 0.193 | G2234: 43516.448
A2235: 2245 | B2235: 43516.451 | C2235: 0.298 | D2235: =C2235-E$2228 -> 0.191 | G2235: 43516.451
...

Sheet Felicita
A1: Plot Title: 11
A2: # | B2: Date Time, GMT-08:00 | C2: Water Level, feet
A3: 1 | B3: 43508.667 | C3: 0
A4: 2 | B4: 43508.67 | C4: 0.003
A5: 3 | B5: 43508.674 | C5: 0.005
A6: 4 | B6: 43508.677 | C6: 0.001
A7: 5 | B7: 43508.681 | C7: 0.007
A8: 6 | B8: 43508.684 | C8: 0.003
A9: 7 | B9: 43508.688 | C9: 0.011
A10: 8 | B10: 43508.691 | C10: 0.008
A11: 9 | B11: 43508.694 | C11: 0.006
A12: 10 | B12: 43508.698 | C12: 0.007
A13: 11 | B13: 43508.701 | C13: 0.003
A14: 12 | B14: 43508.705 | C14: 0.003
... A23: 21 | B23: 43508.736 | C23: 0.008
A24: 22 | B24: 43508.74 | C24: 0.005 | J24: Rain (in) | K24: Offset (ft) | L24: Level (in)
A25: 23 | B25: 43508.743 | C25: 0.004 | J25: ='Feb 13-17 Storm Summary Table'!C3 -> 3.32 | K25: 0 | L25: ='Feb 13-17 Storm Summary Table'!B3-K25 -> 3.179
A26: 24 | B26: 43508.747 | C26: 0.005 | J26: ='Feb 18 Storm Summary Table'!C3 -> 0.32 | K26: 0.5 | L26: ='Feb 18 Storm Summary Table'!B3-K26 -> 0.424
A27: 25 | B27: 43508.75 | C27: 0.004 | J27: ='Feb 20 - 21 Storm Summary Table'!C3 -> 0.59 | K27: 0.5 | L27: ='Feb 20 - 21 Storm Summary Table'!B3-K27 -> 0.644
A28: 26 | B28: 43508.753 | C28: 0.005
A29: 27 | B29: 43508.757 | C29: 0
A30: 28 | B30: 43508.76 | C30: -0.001
A31: 29 | B31: 43508.764 | C31: 0.007
A32: 30 | B32: 43508.767 | C32: 0.003
A33: 31 | B33: 43508.771 | C33: 0.006
A34: 32 | B34: 43508.774 | C34: 0.01
A35: 33 | B35: 43508.778 | C35: 0.003
A36: 34 | B36: 43508.781 | C36: 0.008
A37: 35 | B37: 43508.785 | C37: 0.006
A38: 36 | B38: 43508.788 | C38: 0.005
A39: 37 | B39: 43508.792 | C39: 0.009
... A2247: 2245 | B2247: 43516.458 | C2247: 0.493
A2248: 2246 | B2248: 43516.462 | D2248: 0.493 | E2248: =C2247-C2251 -> 0.119
A2249: 2247 | B2249: 43516.462 | C2249: 0.047 | D2249: 0.493
A2250: 2248 | B2250: 43516.462 | D2250: 0.493
A2251: 2249 | B2251: 43516.465 | C2251: 0.374 | D2251: =C2251+E$2248 -> 0.493
A2252: 2250 | B2252: 43516.469 | C2252: 0.373 | D2252: =C2252+E$2248 -> 0.492
A2253: 2251 | B2253: 43516.472 | C2253: 0.374 | D2253: =C2253+E$2248 -> 0.493
A2254: 2252 | B2254: 43516.476 | C2254: 0.379 | D2254: =C2254+E$2248 -> 0.498
A2255: 2253 | B2255: 43516.479 | C2255: 0.37 | D2255: =C2255+E$2248 -> 0.489
...

Sheet Moonsong
A1: Plot Title: 15
A2: # | B2: Date Time, GMT-08:00 | C2: Water Level, feet | D2: Offset (ft) | E2: Offset Level (ft)
A3: 13 | B3: 43508.708 | C3: 0 | D3: =(7/12)-C$191 -> 0.27633333 | E3: =C3+(D3/12) -> 0.023027778
A4: 14 | B4: 43508.712 | C4: 0.01 | D4: =(7/12)-C$191 -> 0.27633333 | E4: =C4+(D4/12) -> 0.033027778
A5: 15 | B5: 43508.715 | C5: 0.009 | D5: =(7/12)-C$191 -> 0.27633333 | E5: =C5+(D5/12) -> 0.032027778
A6: 16 | B6: 43508.719 | C6: 0.006 | D6: =(7/12)-C$191 -> 0.27633333 | E6: =C6+(D6/12) -> 0.029027778
A7: 17 | B7: 43508.722 | C7: 0.008 | D7: =(7/12)-C$191 -> 0.27633333 | E7: =C7+(D7/12) -> 0.031027778
A8: 18 | B8: 43508.726 | C8: 0.006 | D8: =(7/12)-C$191 -> 0.27633333 | E8: =C8+(D8/12) -> 0.029027778
A9: 19 | B9: 43508.729 | C9: 0.004 | D9: =(7/12)-C$191 -> 0.27633333 | E9: =C9+(D9/12) -> 0.027027778
A10: 20 | B10: 43508.733 | C10: 0.004 | D10: =(7/12)-C$191 -> 0.27633333 | E10: =C10+(D10/12) -> 0.027027778
A11: 21 | B11: 43508.736 | C11: 0.01 | D11: =(7/12)-C$191 -> 0.27633333 | E11: =C11+(D11/12) -> 0.033027778
A12: 22 | B12: 43508.74 | C12: 0.009 | D12: =(7/12)-C$191 -> 0.27633333 | E12: =C12+(D12/12) -> 0.032027778
A13: 23 | B13: 43508.743 | C13: 0.002 | D13: =(7/12)-C$191 -> 0.27633333 | E13: =C13+(D13/12) -> 0.025027778
A14: 24 | B14: 43508.747 | C14: 0.005 | D14: =(7/12)-C$191 -> 0.27633333 | E14: =C14+(D14/12) -> 0.028027778
... A23: 33 | B23: 43508.778 | C23: 0.008 | D23: =(7/12)-C$191 -> 0.27633333 | E23: =C23+(D23/12) -> 0.031027778
A24: 34 | B24: 43508.781 | C24: 0.011 | D24: =(7/12)-C$191 -> 0.27633333 | E24: =C24+(D24/12) -> 0.034027778 | J24: Rain (in) | K24: Offset (ft) | L24: Level (ft)
A25: 35 | B25: 43508.785 | C25: 0.008 | D25: =(7/12)-C$191 -> 0.27633333 | E25: =C25+(D25/12) -> 0.031027778 | J25: ='Feb 13-17 Storm Summary Table'!C4 -> 3.36 | K25: 0 | L25: ='Feb 13-17 Storm Summary Table'!B4-K25 -> 3.2570278
A26: 36 | B26: 43508.788 | C26: 0.014 | D26: =(7/12)-C$191 -> 0.27633333 | E26: =C26+(D26/12) -> 0.037027778 | J26: ='Feb 18 Storm Summary Table'!C4 -> 0.38 | K26: 0.357 | L26: ='Feb 18 Storm Summary Table'!B4-K26 -> 1.0700278
A27: 37 | B27: 43508.792 | C27: 0.008 | D27: =(7/12)-C$191 -> 0.27633333 | E27: =C27+(D27/12) -> 0.031027778 | J27: ='Feb 20 - 21 Storm Summary Table'!C4 -> 0.76 | K27: 0.366 | L27: ='Feb 20 - 21 Storm Summary Table'!B4-K27 -> 1.0270278
A28: 38 | B28: 43508.795 | C28: 0.007 | D28: =(7/12)-C$191 -> 0.27633333 | E28: =C28+(D28/12) -> 0.030027778
A29: 39 | B29: 43508.799 | C29: 0.011 | D29: =(7/12)-C$191 -> 0.27633333 | E29: =C29+(D29/12) -> 0.034027778
A30: 40 | B30: 43508.802 | C30: 0.011 | D30: =(7/12)-C$191 -> 0.27633333 | E30: =C30+(D30/12) -> 0.034027778
A31: 41 | B31: 43508.806 | C31: 0.01 | D31: =(7/12)-C$191 -> 0.27633333 | E31: =C31+(D31/12) -> 0.033027778
A32: 42 | B32: 43508.809 | C32: 0.014 | D32: =(7/12)-C$191 -> 0.27633333 | E32: =C32+(D32/12) -> 0.037027778
A33: 43 | B33: 43508.812 | C33: 0.009 | D33: =(7/12)-C$191 -> 0.27633333 | E33: =C33+(D33/12) -> 0.032027778
A34: 44 | B34: 43508.816 | C34: 0.009 | D34: =(7/12)-C$191 -> 0.27633333 | E34: =C34+(D34/12) -> 0.032027778
A35: 45 | B35: 43508.819 | C35: 0.007 | D35: =(7/12)-C$191 -> 0.27633333 | E35: =C35+(D35/12) -> 0.030027778
A36: 46 | B36: 43508.823 | C36: 0.01 | D36: =(7/12)-C$191 -> 0.27633333 | E36: =C36+(D36/12) -> 0.033027778
A37: 47 | B37: 43508.826 | C37: 0.009 | D37: =(7/12)-C$191 -> 0.27633333 | E37: =C37+(D37/12) -> 0.032027778
A38: 48 | B38: 43508.83 | C38: 0.009 | D38: =(7/12)-C$191 -> 0.27633333 | E38: =C38+(D38/12) -> 0.032027778
A39: 49 | B39: 43508.833 | C39: 0.01 | D39: =(7/12)-C$191 -> 0.27633333 | E39: =C39+(D39/12) -> 0.033027778
... A4260: 4270 | B4260: 43523.49 | C4260: 0.001 | D4260: =(7/12)-C$191 -> 0.27633333 | E4260: =C4260+(D4260/12) -> 0.024027778
A4261: 4271 | B4261: 43523.491
A4262: 4272 | B4262: 43523.491
A4263: 4273 | B4263: 43523.491
A4264: 4274 | B4264: 43523.491
A4265: 4275 | B4265: 43523.491
A4266: 4276 | B4266: 43523.491
A4267: 4277 | B4267: 43523.493
A4268: 4278 | B4268: 43523.497
...

Sheet Green Valley
A1: Plot Title: 17
A2: # | B2: Date Time, GMT-08:00 | C2: Water Level, feet | D2: Offset (ft) | E2: Offset Level (ft)
A3: 13 | B3: 43508.708 | C3: 0 | D3: =(5/12)-C$198 -> 0.072666667 | E3: =C3+D3 -> 0.072666667
A4: 14 | B4: 43508.712 | C4: 0.007 | D4: =(5/12)-C$198 -> 0.072666667 | E4: =C4+D4 -> 0.079666667
A5: 15 | B5: 43508.715 | C5: 0.006 | D5: =(5/12)-C$198 -> 0.072666667 | E5: =C5+D5 -> 0.078666667
A6: 16 | B6: 43508.719 | C6: 0.007 | D6: =(5/12)-C$198 -> 0.072666667 | E6: =C6+D6 -> 0.079666667
A7: 17 | B7: 43508.722 | C7: 0.009 | D7: =(5/12)-C$198 -> 0.072666667 | E7: =C7+D7 -> 0.081666667
A8: 18 | B8: 43508.726 | C8: 0.013 | D8: =(5/12)-C$198 -> 0.072666667 | E8: =C8+D8 -> 0.085666667
A9: 19 | B9: 43508.729 | C9: 0 | D9: =(5/12)-C$198 -> 0.072666667 | E9: =C9+D9 -> 0.072666667
A10: 20 | B10: 43508.733 | C10: 0.01 | D10: =(5/12)-C$198 -> 0.072666667 | E10: =C10+D10 -> 0.082666667
A11: 21 | B11: 43508.736 | C11: 0.012 | D11: =(5/12)-C$198 -> 0.072666667 | E11: =C11+D11 -> 0.084666667
A12: 22 | B12: 43508.74 | C12: 0.012 | D12: =(5/12)-C$198 -> 0.072666667 | E12: =C12+D12 -> 0.084666667
A13: 23 | B13: 43508.743 | C13: 0.004 | D13: =(5/12)-C$198 -> 0.072666667 | E13: =C13+D13 -> 0.076666667
A14: 24 | B14: 43508.747 | C14: 0.009 | D14: =(5/12)-C$198 -> 0.072666667 | E14: =C14+D14 -> 0.081666667
... A23: 33 | B23: 43508.778 | C23: 0.011 | D23: =(5/12)-C$198 -> 0.072666667 | E23: =C23+D23 -> 0.083666667
A24: 34 | B24: 43508.781 | C24: 0.009 | D24: =(5/12)-C$198 -> 0.072666667 | E24: =C24+D24 -> 0.081666667 | J24: Rain (in) | K24: Offset (ft) | L24: Level (ft)
A25: 35 | B25: 43508.785 | C25: 0.004 | D25: =(5/12)-C$198 -> 0.072666667 | E25: =C25+D25 -> 0.076666667 | J25: ='Feb 13-17 Storm Summary Table'!C5 -> 3.36 | K25: 0 | L25: ='Feb 13-17 Storm Summary Table'!B5-K25 -> 4.8426667
A26: 36 | B26: 43508.788 | C26: 0.006 | D26: =(5/12)-C$198 -> 0.072666667 | E26: =C26+D26 -> 0.078666667 | J26: ='Feb 18 Storm Summary Table'!C5 -> 0.38 | K26: 0.279 | L26: ='Feb 18 Storm Summary Table'!B5-K26 -> 0.50866667
A27: 37 | B27: 43508.792 | C27: 0.01 | D27: =(5/12)-C$198 -> 0.072666667 | E27: =C27+D27 -> 0.082666667 | J27: ='Feb 20 - 21 Storm Summary Table'!C5 -> 0.76 | K27: 0.2 | L27: ='Feb 20 - 21 Storm Summary Table'!B5-K27 -> 0.71566667
A28: 38 | B28: 43508.795 | C28: 0.01 | D28: =(5/12)-C$198 -> 0.072666667 | E28: =C28+D28 -> 0.082666667
A29: 39 | B29: 43508.799 | C29: 0.011 | D29: =(5/12)-C$198 -> 0.072666667 | E29: =C29+D29 -> 0.083666667
A30: 40 | B30: 43508.802 | C30: 0.011 | D30: =(5/12)-C$198 -> 0.072666667 | E30: =C30+D30 -> 0.083666667
A31: 41 | B31: 43508.806 | C31: 0.007 | D31: =(5/12)-C$198 -> 0.072666667 | E31: =C31+D31 -> 0.079666667
A32: 42 | B32: 43508.809 | C32: 0.011 | D32: =(5/12)-C$198 -> 0.072666667 | E32: =C32+D32 -> 0.083666667
A33: 43 | B33: 43508.812 | C33: 0.011 | D33: =(5/12)-C$198 -> 0.072666667 | E33: =C33+D33 -> 0.083666667
A34: 44 | B34: 43508.816 | C34: 0.003 | D34: =(5/12)-C$198 -> 0.072666667 | E34: =C34+D34 -> 0.075666667
A35: 45 | B35: 43508.819 | C35: 0.004 | D35: =(5/12)-C$198 -> 0.072666667 | E35: =C35+D35 -> 0.076666667
A36: 46 | B36: 43508.823 | C36: 0.018 | D36: =(5/12)-C$198 -> 0.072666667 | E36: =C36+D36 -> 0.090666667
A37: 47 | B37: 43508.826 | C37: 0.007 | D37: =(5/12)-C$198 -> 0.072666667 | E37: =C37+D37 -> 0.079666667
A38: 48 | B38: 43508.83 | C38: 0.013 | D38: =(5/12)-C$198 -> 0.072666667 | E38: =C38+D38 -> 0.085666667
A39: 49 | B39: 43508.833 | C39: 0.005 | D39: =(5/12)-C$198 -> 0.072666667 | E39: =C39+D39 -> 0.077666667
... A2787: 2797 | B2787: 43518.375 | C2787: 0.22 | D2787: =(5/12)-C$198 -> 0.072666667 | E2787: =C2787+D2787 -> 0.29266667
A2788: 2798 | B2788: 43518.378 | C2788: 0.219 | D2788: =(5/12)-C$198 -> 0.072666667 | E2788: =C2788+D2788 -> 0.29166667 | F2788: Water level below hobo
A2789: 2799 | B2789: 43518.382 | C2789: 0.21 | D2789: =(5/12)-C$198 -> 0.072666667 | E2789: =C2789+D2789 -> 0.28266667
A2790: 2800 | B2790: 43518.385 | C2790: 0.199 | D2790: =(5/12)-C$198 -> 0.072666667 | E2790: =C2790+D2790 -> 0.27166667
A2791: 2801 | B2791: 43518.389 | C2791: 0.2 | D2791: =(5/12)-C$198 -> 0.072666667 | E2791: =C2791+D2791 -> 0.27266667
A2792: 2802 | B2792: 43518.392 | C2792: 0.187 | D2792: =(5/12)-C$198 -> 0.072666667 | E2792: =C2792+D2792 -> 0.25966667
A2793: 2803 | B2793: 43518.396 | C2793: 0.189 | D2793: =(5/12)-C$198 -> 0.072666667 | E2793: =C2793+D2793 -> 0.26166667
A2794: 2804 | B2794: 43518.399 | C2794: 0.179 | D2794: =(5/12)-C$198 -> 0.072666667 | E2794: =C2794+D2794 -> 0.25166667
A2795: 2805 | B2795: 43518.403 | C2795: 0.173 | D2795: =(5/12)-C$198 -> 0.072666667 | E2795: =C2795+D2795 -> 0.24566667
...

Sheet Sycamore Creek
A1: Plot Title: 10
A2: # | B2: Date Time, GMT-08:00 | C2: Water Level, feet
A3: 1 | B3: 43508.667 | C3: 0
A4: 2 | B4: 43508.67 | C4: 0.007
A5: 3 | B5: 43508.674 | C5: 0.006
A6: 4 | B6: 43508.677 | C6: 0.004
A7: 5 | B7: 43508.681 | C7: 0.008
A8: 6 | B8: 43508.684 | C8: 0.011
A9: 7 | B9: 43508.688 | C9: 0.007
A10: 8 | B10: 43508.691 | C10: 0.011
A11: 9 | B11: 43508.694 | C11: 0.006
A12: 10 | B12: 43508.698 | C12: 0.009
A13: 11 | B13: 43508.701 | C13: 0.008
A14: 12 | B14: 43508.705 | C14: 0.006
... A23: 21 | B23: 43508.736 | C23: 0.007
A24: 22 | B24: 43508.74 | C24: 0.011 | J24: Rain (in) | K24: Offset (ft) | L24: Level (ft)
A25: 23 | B25: 43508.743 | C25: 0.004 | J25: ='Feb 13-17 Storm Summary Table'!C6 -> 3.25 | K25: 0 | L25: ='Feb 13-17 Storm Summary Table'!B6-K25 -> 5.123
A26: 24 | B26: 43508.747 | C26: 0.007 | J26: ='Feb 18 Storm Summary Table'!C6 -> 0.37 | K26: 0 | L26: ='Feb 18 Storm Summary Table'!B6-K26 -> 0.653
A27: 25 | B27: 43508.75 | C27: 0.01 | J27: ='Feb 20 - 21 Storm Summary Table'!C6 -> 0.78 | K27: 0 | L27: ='Feb 20 - 21 Storm Summary Table'!B6-K27 -> 1.787
A28: 26 | B28: 43508.753 | C28: 0.009
A29: 27 | B29: 43508.757 | C29: 0.009
A30: 28 | B30: 43508.76 | C30: 0.003
A31: 29 | B31: 43508.764 | C31: 0.009
A32: 30 | B32: 43508.767 | C32: 0.005
A33: 31 | B33: 43508.771 | C33: 0.007
A34: 32 | B34: 43508.774 | C34: 0.012
A35: 33 | B35: 43508.778 | C35: 0.008
A36: 34 | B36: 43508.781 | C36: 0.008
A37: 35 | B37: 43508.785 | C37: 0.008
A38: 36 | B38: 43508.788 | C38: 0.011
A39: 37 | B39: 43508.792 | C39: 0.006
... A2289: 2287 | B2289: 43516.604 | C2289: 0.016
A2290: 2288 | B2290: 43516.607
A2291: 2289 | B2291: 43516.607
A2292: 2290 | B2292: 43516.608 | C2292: -0.006
A2293: 2291 | B2293: 43516.611 | C2293: 0.004
A2294: 2292 | B2294: 43516.615 | C2294: 0.001
A2295: 2293 | B2295: 43516.618 | C2295: 0.008
A2296: 2294 | B2296: 43516.622 | C2296: 0.007
A2297: 2295 | B2297: 43516.625 | C2297: 0.003
...

Sheet Kit Carson Creek
A1: Plot Title: 8
A2: # | B2: Date Time, GMT-08:00 | C2: Water Level, feet | D2: Offset (ft) | E2: Offset Level (ft)
A3: 1 | B3: 43508.667 | C3: 0 | D3: =(4/12)-C$256 -> 0.045333333 | E3: =C3+D3 -> 0.045333333
A4: 2 | B4: 43508.67 | C4: 0.006 | D4: =(4/12)-C$256 -> 0.045333333 | E4: =C4+D4 -> 0.051333333
A5: 3 | B5: 43508.674 | C5: 0.002 | D5: =(4/12)-C$256 -> 0.045333333 | E5: =C5+D5 -> 0.047333333
A6: 4 | B6: 43508.677 | C6: 0.005 | D6: =(4/12)-C$256 -> 0.045333333 | E6: =C6+D6 -> 0.050333333
A7: 5 | B7: 43508.681 | C7: 0.009 | D7: =(4/12)-C$256 -> 0.045333333 | E7: =C7+D7 -> 0.054333333
A8: 6 | B8: 43508.684 | C8: 0.008 | D8: =(4/12)-C$256 -> 0.045333333 | E8: =C8+D8 -> 0.053333333
A9: 7 | B9: 43508.688 | C9: 0.008 | D9: =(4/12)-C$256 -> 0.045333333 | E9: =C9+D9 -> 0.053333333
A10: 8 | B10: 43508.691 | C10: 0.008 | D10: =(4/12)-C$256 -> 0.045333333 | E10: =C10+D10 -> 0.053333333
A11: 9 | B11: 43508.694 | C11: 0.007 | D11: =(4/12)-C$256 -> 0.045333333 | E11: =C11+D11 -> 0.052333333
A12: 10 | B12: 43508.698 | C12: 0.006 | D12: =(4/12)-C$256 -> 0.045333333 | E12: =C12+D12 -> 0.051333333
A13: 11 | B13: 43508.701 | C13: 0.006 | D13: =(4/12)-C$256 -> 0.045333333 | E13: =C13+D13 -> 0.051333333
A14: 12 | B14: 43508.705 | C14: -0.001 | D14: =(4/12)-C$256 -> 0.045333333 | E14: =C14+D14 -> 0.044333333
... A23: 21 | B23: 43508.736 | C23: 0.007 | D23: =(4/12)-C$256 -> 0.045333333 | E23: =C23+D23 -> 0.052333333
A24: 22 | B24: 43508.74 | C24: 0.004 | D24: =(4/12)-C$256 -> 0.045333333 | E24: =C24+D24 -> 0.049333333 | J24: Rain (in) | K24: Offset (ft) | L24: Level (in)
A25: 23 | B25: 43508.743 | C25: 0.004 | D25: =(4/12)-C$256 -> 0.045333333 | E25: =C25+D25 -> 0.049333333 | J25: ='Feb 13-17 Storm Summary Table'!C7 -> 3.32 | K25: 0 | L25: ='Feb 13-17 Storm Summary Table'!B7-K25 -> 3.8493333
A26: 24 | B26: 43508.747 | C26: 0.003 | D26: =(4/12)-C$256 -> 0.045333333 | E26: =C26+D26 -> 0.048333333 | J26: ='Feb 18 Storm Summary Table'!C7 -> 0.32 | K26: 0.482 | L26: ='Feb 18 Storm Summary Table'!B7-K26 -> 0.48733333
A27: 25 | B27: 43508.75 | C27: 0.01 | D27: =(4/12)-C$256 -> 0.045333333 | E27: =C27+D27 -> 0.055333333 | J27: ='Feb 20 - 21 Storm Summary Table'!C7 -> 0.59 | K27: 0.417 | L27: ='Feb 20 - 21 Storm Summary Table'!B7-K27 -> 0.49633333
A28: 26 | B28: 43508.753 | C28: 0.005 | D28: =(4/12)-C$256 -> 0.045333333 | E28: =C28+D28 -> 0.050333333
A29: 27 | B29: 43508.757 | C29: -0.001 | D29: =(4/12)-C$256 -> 0.045333333 | E29: =C29+D29 -> 0.044333333
A30: 28 | B30: 43508.76 | C30: -0.001 | D30: =(4/12)-C$256 -> 0.045333333 | E30: =C30+D30 -> 0.044333333
A31: 29 | B31: 43508.764 | C31: 0.007 | D31: =(4/12)-C$256 -> 0.045333333 | E31: =C31+D31 -> 0.052333333
A32: 30 | B32: 43508.767 | C32: -0.001 | D32: =(4/12)-C$256 -> 0.045333333 | E32: =C32+D32 -> 0.044333333
A33: 31 | B33: 43508.771 | C33: -0.005 | D33: =(4/12)-C$256 -> 0.045333333 | E33: =C33+D33 -> 0.040333333
A34: 32 | B34: 43508.774 | C34: 0.004 | D34: =(4/12)-C$256 -> 0.045333333 | E34: =C34+D34 -> 0.049333333
A35: 33 | B35: 43508.778 | C35: 0.003 | D35: =(4/12)-C$256 -> 0.045333333 | E35: =C35+D35 -> 0.048333333
A36: 34 | B36: 43508.781 | C36: 0.005 | D36: =(4/12)-C$256 -> 0.045333333 | E36: =C36+D36 -> 0.050333333
A37: 35 | B37: 43508.785 | C37: 0 | D37: =(4/12)-C$256 -> 0.045333333 | E37: =C37+D37 -> 0.045333333
A38: 36 | B38: 43508.788 | C38: 0.002 | D38: =(4/12)-C$256 -> 0.045333333 | E38: =C38+D38 -> 0.047333333
A39: 37 | B39: 43508.792 | C39: 0.003 | D39: =(4/12)-C$256 -> 0.045333333 | E39: =C39+D39 -> 0.048333333
... A2294: 2292 | B2294: 43516.622 | C2294: 0.404 | D2294: =(4/12)-C$256 -> 0.045333333 | E2294: =C2294+D2294 -> 0.44933333
A2295: 2293 | B2295: 43516.624 | D2295: =(4/12)-C$256 -> 0.045333333 | E2295: =AVERAGE(E2290:E2294) -> 0.44993333
A2296: 2294 | B2296: 43516.625 | C2296: -0.05 | D2296: =(4/12)-C$256 -> 0.045333333 | E2296: =AVERAGE(E2291:E2295) -> 0.45045333
A2297: 2295 | B2297: 43516.625 | D2297: =(4/12)-C$256 -> 0.045333333 | E2297: =AVERAGE(E2292:E2296) -> 0.45107733
A2298: 2296 | B2298: 43516.628 | C2298: -0.041 | D2298: =(4/12)-C$256 -> 0.045333333 | E2298: =AVERAGE(E2293:E2297) -> 0.45062613
A2299: 2297 | B2299: 43516.632 | C2299: -0.033 | D2299: =(4/12)-C$256 -> 0.045333333 | E2299: =AVERAGE(E2294:E2298) -> 0.45028469
A2300: 2298 | B2300: 43516.635 | C2300: 0.372 | D2300: =(4/12)-C$256 -> 0.045333333 | E2300: =C2300+D2300 -> 0.41733333
A2301: 2299 | B2301: 43516.639 | C2301: 0.374 | D2301: =(4/12)-C$256 -> 0.045333333 | E2301: =C2301+D2301 -> 0.41933333
A2302: 2300 | B2302: 43516.642 | C2302: 0.372 | D2302: =(4/12)-C$256 -> 0.045333333 | E2302: =C2302+D2302 -> 0.41733333
...

Sheet Cloverdale
A1: Plot Title: 2
A2: # | B2: Date Time, GMT-08:00 | C2: Water Level, feet
A3: 1 | B3: 43508.667 | C3: 0
A4: 2 | B4: 43508.67 | C4: 0.006
A5: 3 | B5: 43508.674 | C5: 0.006
A6: 4 | B6: 43508.677 | C6: 0.006
A7: 5 | B7: 43508.681 | C7: 0.01
A8: 6 | B8: 43508.684 | C8: 0.006
A9: 7 | B9: 43508.688 | C9: 0.007
A10: 8 | B10: 43508.691 | C10: 0.006
A11: 9 | B11: 43508.694 | C11: 0.01
A12: 10 | B12: 43508.698 | C12: 0.009
A13: 11 | B13: 43508.701 | C13: 0.006
A14: 12 | B14: 43508.705 | C14: 0.002
... A23: 21 | B23: 43508.736 | C23: 0.009
A24: 22 | B24: 43508.74 | C24: 0.007 | J24: Rain (in) | K24: Offset (ft) | L24: Level (ft)
A25: 23 | B25: 43508.743 | C25: 0.006 | J25: ='Feb 13-17 Storm Summary Table'!C8 -> 3.19 | K25: 0 | L25: ='Feb 13-17 Storm Summary Table'!B8-K25 -> 3.463
A26: 24 | B26: 43508.747 | C26: 0.007 | J26: ='Feb 18 Storm Summary Table'!C8 -> 0.32 | K26: 0 | L26: -
A27: 25 | B27: 43508.75 | C27: 0.01 | J27: ='Feb 20 - 21 Storm Summary Table'!C8 -> 0.69 | K27: 0.86 | L27: ='Feb 20 - 21 Storm Summary Table'!B8-K27 -> 0.527 | M27: <-need to offset this one
A28: 26 | B28: 43508.753 | C28: 0.005
A29: 27 | B29: 43508.757 | C29: 0.006
A30: 28 | B30: 43508.76 | C30: 0.003
A31: 29 | B31: 43508.764 | C31: 0.013
A32: 30 | B32: 43508.767 | C32: 0.01
A33: 31 | B33: 43508.771 | C33: 0.006
A34: 32 | B34: 43508.774 | C34: 0.015
A35: 33 | B35: 43508.778 | C35: 0.01
A36: 34 | B36: 43508.781 | C36: 0.016
A37: 35 | B37: 43508.785 | C37: 0.011
A38: 36 | B38: 43508.788 | C38: 0.009
A39: 37 | B39: 43508.792 | C39: 0.01
... A4330: 4328 | B4330: 43523.691 | C4330: -0.053
A4331: 4329 | B4331: 43523.691
A4332: 4330 | B4332: 43523.694
A4333: 4331 | B4333: 43523.698
A4334: 4332 | B4334: 43523.701
A4335: 4333 | B4335: 43523.705

Sheet Guejito Creek
A1: Plot Title: 12
A2: # | B2: Date Time, GMT-08:00 | C2: Water Level, feet | D2: Offset (ft) | E2: Offset Level (ft) | F2: Filtered Level (ft)
A3: 1 | B3: 43508.667 | C3: 0 | D3: 0.15 | E3: =C3+D3 -> 0.15 | F3: =IF(E3<0,0,E3) -> 0.15
A4: 2 | B4: 43508.67 | C4: 0.024 | D4: 0.15 | E4: =C4+D4 -> 0.174 | F4: =IF(E4<0,0,E4) -> 0.174
A5: 3 | B5: 43508.674 | C5: 0.024 | D5: 0.15 | E5: =C5+D5 -> 0.174 | F5: =IF(E5<0,0,E5) -> 0.174
A6: 4 | B6: 43508.677 | C6: 0.027 | D6: 0.15 | E6: =C6+D6 -> 0.177 | F6: =IF(E6<0,0,E6) -> 0.177
A7: 5 | B7: 43508.681 | C7: 0.029 | D7: 0.15 | E7: =C7+D7 -> 0.179 | F7: =IF(E7<0,0,E7) -> 0.179
A8: 6 | B8: 43508.684 | C8: 0.031 | D8: 0.15 | E8: =C8+D8 -> 0.181 | F8: =IF(E8<0,0,E8) -> 0.181
A9: 7 | B9: 43508.688 | C9: 0.033 | D9: 0.15 | E9: =C9+D9 -> 0.183 | F9: =IF(E9<0,0,E9) -> 0.183
A10: 8 | B10: 43508.691 | C10: 0.032 | D10: 0.15 | E10: =C10+D10 -> 0.182 | F10: =IF(E10<0,0,E10) -> 0.182
A11: 9 | B11: 43508.694 | C11: 0.031 | D11: 0.15 | E11: =C11+D11 -> 0.181 | F11: =IF(E11<0,0,E11) -> 0.181
A12: 10 | B12: 43508.698 | C12: 0.03 | D12: 0.15 | E12: =C12+D12 -> 0.18 | F12: =IF(E12<0,0,E12) -> 0.18
A13: 11 | B13: 43508.701 | C13: 0.029 | D13: 0.15 | E13: =C13+D13 -> 0.179 | F13: =IF(E13<0,0,E13) -> 0.179
A14: 12 | B14: 43508.705 | C14: 0.026 | D14: 0.15 | E14: =C14+D14 -> 0.176 | F14: =IF(E14<0,0,E14) -> 0.176
... A23: 21 | B23: 43508.736 | C23: 0.029 | D23: 0.15 | E23: =C23+D23 -> 0.179 | F23: =IF(E23<0,0,E23) -> 0.179
A24: 22 | B24: 43508.74 | C24: 0.03 | D24: 0.15 | E24: =C24+D24 -> 0.18 | F24: =IF(E24<0,0,E24) -> 0.18 | J24: Rain (in) | K24: Level (ft)
A25: 23 | B25: 43508.743 | C25: 0.022 | D25: 0.15 | E25: =C25+D25 -> 0.172 | F25: =IF(E25<0,0,E25) -> 0.172 | J25: ='Feb 13-17 Storm Summary Table'!C9 -> 3.46 | K25: ='Feb 13-17 Storm Summary Table'!B9 -> 5.998
A26: 24 | B26: 43508.747 | C26: 0.025 | D26: 0.15 | E26: =C26+D26 -> 0.175 | F26: =IF(E26<0,0,E26) -> 0.175 | J26: ='Feb 18 Storm Summary Table'!C9 -> 0.32 | K26: ='Feb 18 Storm Summary Table'!B9 -> 0.308 | M26: No offsets necessary, this actually looks like a reasonable rating curve
A27: 25 | B27: 43508.75 | C27: 0.029 | D27: 0.15 | E27: =C27+D27 -> 0.179 | F27: =IF(E27<0,0,E27) -> 0.179 | J27: ='Feb 20 - 21 Storm Summary Table'!C9 -> 0.8 | K27: ='Feb 20 - 21 Storm Summary Table'!B9 -> 0.602
A28: 26 | B28: 43508.753 | C28: 0.027 | D28: 0.15 | E28: =C28+D28 -> 0.177 | F28: =IF(E28<0,0,E28) -> 0.177
A29: 27 | B29: 43508.757 | C29: 0.025 | D29: 0.15 | E29: =C29+D29 -> 0.175 | F29: =IF(E29<0,0,E29) -> 0.175
A30: 28 | B30: 43508.76 | C30: 0.021 | D30: 0.15 | E30: =C30+D30 -> 0.171 | F30: =IF(E30<0,0,E30) -> 0.171
A31: 29 | B31: 43508.764 | C31: 0.026 | D31: 0.15 | E31: =C31+D31 -> 0.176 | F31: =IF(E31<0,0,E31) -> 0.176
A32: 30 | B32: 43508.767 | C32: 0.026 | D32: 0.15 | E32: =C32+D32 -> 0.176 | F32: =IF(E32<0,0,E32) -> 0.176
A33: 31 | B33: 43508.771 | C33: 0.021 | D33: 0.15 | E33: =C33+D33 -> 0.171 | F33: =IF(E33<0,0,E33) -> 0.171
A34: 32 | B34: 43508.774 | C34: 0.033 | D34: 0.15 | E34: =C34+D34 -> 0.183 | F34: =IF(E34<0,0,E34) -> 0.183
A35: 33 | B35: 43508.778 | C35: 0.026 | D35: 0.15 | E35: =C35+D35 -> 0.176 | F35: =IF(E35<0,0,E35) -> 0.176
A36: 34 | B36: 43508.781 | C36: 0.028 | D36: 0.15 | E36: =C36+D36 -> 0.178 | F36: =IF(E36<0,0,E36) -> 0.178
A37: 35 | B37: 43508.785 | C37: 0.029 | D37: 0.15 | E37: =C37+D37 -> 0.179 | F37: =IF(E37<0,0,E37) -> 0.179
A38: 36 | B38: 43508.788 | C38: 0.026 | D38: 0.15 | E38: =C38+D38 -> 0.176 | F38: =IF(E38<0,0,E38) -> 0.176
A39: 37 | B39: 43508.792 | C39: 0.029 | D39: 0.15 | E39: =C39+D39 -> 0.179 | F39: =IF(E39<0,0,E39) -> 0.179
... A4291: 4289 | B4291: 43523.556 | C4291: -0.286 | D4291: 0.15 | E4291: =C4291+D4291 -> -0.136 | F4291: =IF(E4291<0,0,E4291) -> 0
A4292: 4290 | B4292: 43523.558
A4293: 4291 | B4293: 43523.559
A4294: 4292 | B4294: 43523.562
A4295: 4293 | B4295: 43523.566
A4296: 4294 | B4296: 43523.569
A4297: 4295 | B4297: 43523.573
A4298: 4296 | B4298: 43523.576
A4299: 4297 | B4299: 43523.58
...

Sheet Combined Plot

Sheet ESRI_MAPINFO_SHEET
