Workbook

Sheet Flow Data
A1: Date and Time | B1: Date | C1: Time | D1: Level | E1: Vel. 1 | F1: Flow 1 | G1: Flow 5 minute ave
D2: (in.) | E2: (fps) | F2: (gpm) | G2: (gpm)
A3: =B3+C3 -> 43853.628 | B3: 43853 | C3: 0.62847222 | D3: 1.701 | E3: 0 | F3: 0
A4: =B4+C4 -> 43853.632 | B4: 43853 | C4: 0.63194444 | D4: 0 | E4: 0 | F4: 0
A5: =B5+C5 -> 43853.635 | B5: 43853 | C5: 0.63541667 | D5: 0 | E5: 0 | F5: 0 | G5: =AVERAGE(F3:F7) -> 0
A6: =B6+C6 -> 43853.639 | B6: 43853 | C6: 0.63888889 | D6: 0 | E6: 0 | F6: 0 | G6: =AVERAGE(F4:F8) -> 0
A7: =B7+C7 -> 43853.642 | B7: 43853 | C7: 0.64236111 | D7: 0 | E7: 0 | F7: 0 | G7: =AVERAGE(F5:F9) -> 0
A8: =B8+C8 -> 43853.646 | B8: 43853 | C8: 0.64583333 | D8: 0 | E8: 0 | F8: 0 | G8: =AVERAGE(F6:F10) -> 0
A9: =B9+C9 -> 43853.649 | B9: 43853 | C9: 0.64930556 | D9: 0 | E9: 0 | F9: 0 | G9: =AVERAGE(F7:F11) -> 0
A10: =B10+C10 -> 43853.653 | B10: 43853 | C10: 0.65277778 | D10: 0 | E10: 0 | F10: 0 | G10: =AVERAGE(F8:F12) -> 0
A11: =B11+C11 -> 43853.656 | B11: 43853 | C11: 0.65625 | D11: 0 | E11: 0 | F11: 0 | G11: =AVERAGE(F9:F13) -> 0
A12: =B12+C12 -> 43853.66 | B12: 43853 | C12: 0.65972222 | D12: 0 | E12: 0 | F12: 0 | G12: =AVERAGE(F10:F14) -> 0
A13: =B13+C13 -> 43853.663 | B13: 43853 | C13: 0.66319444 | D13: 0 | E13: 0 | F13: 0 | G13: =AVERAGE(F11:F15) -> 0
A14: =B14+C14 -> 43853.667 | B14: 43853 | C14: 0.66666667 | D14: 0 | E14: 0 | F14: 0 | G14: =AVERAGE(F12:F16) -> 0
A15: =B15+C15 -> 43853.67 | B15: 43853 | C15: 0.67013889 | D15: 0 | E15: 0 | F15: 0 | G15: =AVERAGE(F13:F17) -> 0
A16: =B16+C16 -> 43853.674 | B16: 43853 | C16: 0.67361111 | D16: 0 | E16: 0 | F16: 0 | G16: =AVERAGE(F14:F18) -> 0
... A21427: =B21427+C21427 -> 43928.101 | B21427: 43928 | C21427: 0.10069444 | D21427: 3.2 | E21427: 4.13 | F21427: 687.176 | G21427: =AVERAGE(F21425:F21429) -> 802.9644
A21428: =B21428+C21428 -> 43928.104 | B21428: 43928 | C21428: 0.10416667 | D21428: 3.394 | E21428: 3.44 | F21428: 616.202 | G21428: =AVERAGE(F21426:F21429) -> 668.3965
A21429: =B21429+C21429 -> 43928.108 | B21429: 43928 | C21429: 0.10763889 | D21429: 1.866 | E21429: 3.34 | F21429: 286.059 | G21429: =AVERAGE(F21427:F21430) -> 415.9985
A21430: =B21430+C21430 -> 43928.118 | B21430: 43928 | C21430: 0.11805556 | D21430: 0.664 | E21430: 2.78 | F21430: 74.557 | G21430: =AVERAGE(F21428:F21431) -> 276.28975
A21431: =B21431+C21431 -> 43928.122 | B21431: 43928 | C21431: 0.12152778 | D21431: 1.3 | E21431: 2.28 | F21431: 128.341 | G21431: =AVERAGE(F21429:F21432) -> 148.813
A21432: =B21432+C21432 -> 43928.125 | B21432: 43928 | C21432: 0.125 | D21432: 1.155 | E21432: 2.16 | F21432: 106.295 | G21432: =AVERAGE(F21430:F21433) -> 102.2565
A21433: =B21433+C21433 -> 43928.128 | B21433: 43928 | C21433: 0.12847222 | D21433: 1.147 | E21433: 2.04 | F21433: 99.833 | G21433: =AVERAGE(F21431:F21434) -> 111.3685
A21434: =B21434+C21434 -> 43928.132 | B21434: 43928 | C21434: 0.13194444 | D21434: 1.181 | E21434: 2.2 | F21434: 111.005 | G21434: =AVERAGE(F21432:F21435) -> 110.3355
A21435: =B21435+C21435 -> 43928.135 | B21435: 43928 | C21435: 0.13541667 | D21435: 1.232 | E21435: 2.34 | F21435: 124.209 | G21435: =AVERAGE(F21433:F21436) -> 112.253
A21436: =B21436+C21436 -> 43928.139 | B21436: 43928 | C21436: 0.13888889 | D21436: 1.224 | E21436: 2.17 | F21436: 113.965 | G21436: =AVERAGE(F21434:F21437) -> 111.863
A21437: =B21437+C21437 -> 43928.142 | B21437: 43928 | C21437: 0.14236111 | D21437: 1.198 | E21437: 1.91 | F21437: 98.273 | G21437: =AVERAGE(F21435:F21438) -> 105.7965
A21438: =B21438+C21438 -> 43928.146 | B21438: 43928 | C21438: 0.14583333 | D21438: 1.155 | E21438: 1.76 | F21438: 86.739 | G21438: =AVERAGE(F21436:F21439) -> 95.273
A21439: =B21439+C21439 -> 43928.149 | B21439: 43928 | C21439: 0.14930556 | D21439: 1.138 | E21439: 1.69 | F21439: 82.115 | G21439: =AVERAGE(F21437:F21440) -> 88.38525
... A21887: =B21887+C21887 -> 43929.705 | B21887: 43929 | C21887: 0.70486111 | D21887: 0.056 | E21887: 0 | F21887: 0 | G21887: =AVERAGE(F21885:F21888) -> 0
A21888: 43968.681 | E21888: 0 | F21888: 0 | G21888: =AVERAGE(F21886:F21889) -> 0
A21889: 43968.684 | E21889: 0 | F21889: 0 | G21889: =AVERAGE(F21887:F21890) -> 0
A21890: 43968.688 | E21890: 0 | F21890: 0 | G21890: =AVERAGE(F21888:F21891) -> 0
A21891: 43968.691 | E21891: 0 | F21891: 0 | G21891: =AVERAGE(F21889:F21892) -> 0
A21892: 43968.694 | E21892: 0 | F21892: 0 | G21892: =AVERAGE(F21890:F21893) -> 0
A21893: 43968.698 | E21893: 0 | F21893: 0 | G21893: =AVERAGE(F21891:F21894) -> 0
A21894: 43968.701 | E21894: 0 | F21894: 0 | G21894: =AVERAGE(F21892:F21895) -> 0
A21895: 43968.705 | E21895: 0 | F21895: 0 | G21895: =AVERAGE(F21893:F21896) -> 0
A21896: 43968.708 | E21896: 0 | F21896: 0 | G21896: =AVERAGE(F21894:F21897) -> 0
A21897: 43968.712 | E21897: 0 | F21897: 0 | G21897: =AVERAGE(F21895:F21898) -> 0
...

Sheet Filtered Flow Data
A1: Date and Time | B1: Date | C1: Time | D1: Level | E1: Vel. 1 | F1: Flow 1 | G1: Flow 5 minute ave | I1: Regression Flow | J1: Absolute Error | K1: Abs Error Squared | L1: Relative Error | M1: RMSE | O1: Manning's Flow | P1: Absolute Error | Q1: Abs Error Squared | R1: Relative Error | S1: RMSE
D2: (in.) | E2: (fps) | F2: (gpm) | G2: (gpm) | I2: (gpm) | J2: (gpm) | L2: (%) | M2: (gpm) | O2: (gpm) | P2: (gpm) | R2: (%) | S2: (gpm)
A3: 43859.528 | B3: 43859 | C3: 0.52777778 | D3: 0.65 | E3: 2.36 | F3: 61.803 | G3: 35.0686 | I3: =26.666*(D3^2.1619) -> 10.5074 | J3: =ABS(I3-F3) -> 51.2956 | K3: =J3^2 -> 2631.2386 | L3: =100*ABS(J3/I3) -> 488.18548 | M3: =SQRT(SUM(K3:K2444)/ROWS(K3:K2444)) -> 186.39795 | O3: =VLOOKUP(D3,'Manning''s Flow'!I$10:J$2010,2,TRUE) -> 42.902017 | P3: =ABS(F3-O3) -> 18.900983 | Q3: =P3^2 -> 357.24717 | R3: =100*ABS(P3/O3) -> 44.056165 | S3: =SQRT(SUM(Q3:Q38304)/ROWS(Q3:Q38304)) -> 20.496886
A4: 43859.531 | B4: 43859 | C4: 0.53125 | D4: 0.948 | E4: 2.57 | F4: 101.698 | G4: 35.4466 | I4: =26.666*(D4^2.1619) -> 23.758544 | J4: =ABS(I4-F4) -> 77.939456 | K4: =J4^2 -> 6074.5588 | L4: =100*ABS(J4/I4) -> 328.04812 | O4: =VLOOKUP(D4,'Manning''s Flow'!I$10:J$2010,2,TRUE) -> 81.841624 | P4: =ABS(F4-O4) -> 19.856376 | Q4: =P4^2 -> 394.27567 | R4: =100*ABS(P4/O4) -> 24.261953
A5: 43859.535 | B5: 43859 | C5: 0.53472222 | D5: 0.237 | E5: 1.3 | F5: 11.842 | G5: 35.4466 | I5: =26.666*(D5^2.1619) -> 1.1863868 | J5: =ABS(I5-F5) -> 10.655613 | K5: =J5^2 -> 113.54209 | L5: =100*ABS(J5/I5) -> 898.15671 | O5: =VLOOKUP(D5,'Manning''s Flow'!I$10:J$2010,2,TRUE) -> 7.4251265 | P5: =ABS(F5-O5) -> 4.4168735 | Q5: =P5^2 -> 19.508772 | R5: =100*ABS(P5/O5) -> 59.485499
A6: 43859.538 | B6: 43859 | C6: 0.53819444 | D6: 0.123 | E6: 0.4 | F6: 1.89 | G6: 23.086 | I6: =26.666*(D6^2.1619) -> 0.28735829 | J6: =ABS(I6-F6) -> 1.6026417 | K6: =J6^2 -> 2.5684604 | L6: =100*ABS(J6/I6) -> 557.71549 | O6: =VLOOKUP(D6,'Manning''s Flow'!I$10:J$2010,2,TRUE) -> 2.5409647 | P6: =ABS(F6-O6) -> 0.65096474 | Q6: =P6^2 -> 0.42375509 | R6: =100*ABS(P6/O6) -> 25.618802
A7: 43866.872 | B7: 43866 | C7: 0.87152778 | D7: 0.252 | E7: 0.18 | F7: 1.755 | G7: 2.2222 | I7: =26.666*(D7^2.1619) -> 1.354708 | J7: =ABS(I7-F7) -> 0.40029197 | K7: =J7^2 -> 0.16023366 | L7: =100*ABS(J7/I7) -> 29.54821 | O7: =VLOOKUP(D7,'Manning''s Flow'!I$10:J$2010,2,TRUE) -> 8.7784268 | P7: =ABS(F7-O7) -> 7.0234268 | Q7: =P7^2 -> 49.328523 | R7: =100*ABS(P7/O7) -> 80.007807
A8: 43866.875 | B8: 43866 | C8: 0.875 | D8: 0.288 | E8: 0.61 | F8: 6.81 | G8: 2.2222 | I8: =26.666*(D8^2.1619) -> 1.8080835 | J8: =ABS(I8-F8) -> 5.0019165 | K8: =J8^2 -> 25.019168 | L8: =100*ABS(J8/I8) -> 276.64189 | O8: =VLOOKUP(D8,'Manning''s Flow'!I$10:J$2010,2,TRUE) -> 10.222141 | P8: =ABS(F8-O8) -> 3.4121415 | Q8: =P8^2 -> 11.64271 | R8: =100*ABS(P8/O8) -> 33.379909
A9: 43866.878 | B9: 43866 | C9: 0.87847222 | D9: 0.21 | E9: 0.32 | F9: 2.546 | G9: 2.2222 | I9: =26.666*(D9^2.1619) -> 0.91340581 | J9: =ABS(I9-F9) -> 1.6325942 | K9: =J9^2 -> 2.6653638 | L9: =100*ABS(J9/I9) -> 178.73701 | O9: =VLOOKUP(D9,'Manning''s Flow'!I$10:J$2010,2,TRUE) -> 6.1650108 | P9: =ABS(F9-O9) -> 3.6190108 | Q9: =P9^2 -> 13.097239 | R9: =100*ABS(P9/O9) -> 58.702425
A10: 43870.573 | B10: 43870 | C10: 0.57291667 | D10: 0.244 | E10: 1.09 | F10: 10.196 | G10: 46.2314 | I10: =26.666*(D10^2.1619) -> 1.2634438 | J10: =ABS(I10-F10) -> 8.9325562 | K10: =J10^2 -> 79.79056 | L10: =100*ABS(J10/I10) -> 707.00065 | O10: =VLOOKUP(D10,'Manning''s Flow'!I$10:J$2010,2,TRUE) -> 8.0903111 | P10: =ABS(F10-O10) -> 2.1056889 | Q10: =P10^2 -> 4.4339257 | R10: =100*ABS(P10/O10) -> 26.027292
A11: 43870.576 | B11: 43870 | C11: 0.57638889 | D11: 0.654 | E11: 2.21 | F11: 58.355 | G11: 89.861 | I11: =26.666*(D11^2.1619) -> 10.64769 | J11: =ABS(I11-F11) -> 47.70731 | K11: =J11^2 -> 2275.9874 | L11: =100*ABS(J11/I11) -> 448.05313 | O11: =VLOOKUP(D11,'Manning''s Flow'!I$10:J$2010,2,TRUE) -> 42.902017 | P11: =ABS(F11-O11) -> 15.452983 | Q11: =P11^2 -> 238.79469 | R11: =100*ABS(P11/O11) -> 36.019247
A12: 43870.58 | B12: 43870 | C12: 0.57986111 | D12: 1.194 | E12: 3.18 | F12: 162.606 | G12: 124.2596 | I12: =26.666*(D12^2.1619) -> 39.123124 | J12: =ABS(I12-F12) -> 123.48288 | K12: =J12^2 -> 15248.021 | L12: =100*ABS(J12/I12) -> 315.62632 | O12: =VLOOKUP(D12,'Manning''s Flow'!I$10:J$2010,2,TRUE) -> 120.46616 | P12: =ABS(F12-O12) -> 42.139838 | Q12: =P12^2 -> 1775.766 | R12: =100*ABS(P12/O12) -> 34.980643
A13: 43870.583 | B13: 43870 | C13: 0.58333333 | D13: 1.269 | E13: 3.98 | F13: 218.148 | G13: 152.9764 | I13: =26.666*(D13^2.1619) -> 44.63048 | J13: =ABS(I13-F13) -> 173.51752 | K13: =J13^2 -> 30108.33 | L13: =100*ABS(J13/I13) -> 388.78704 | O13: =VLOOKUP(D13,'Manning''s Flow'!I$10:J$2010,2,TRUE) -> 133.31652 | P13: =ABS(F13-O13) -> 84.831478 | Q13: =P13^2 -> 7196.3797 | R13: =100*ABS(P13/O13) -> 63.631632
A14: 43870.587 | B14: 43870 | C14: 0.58680556 | D14: 1.131 | E14: 3.58 | F14: 171.993 | G14: 161.2152 | I14: =26.666*(D14^2.1619) -> 34.79675 | J14: =ABS(I14-F14) -> 137.19625 | K14: =J14^2 -> 18822.811 | L14: =100*ABS(J14/I14) -> 394.27892 | O14: =VLOOKUP(D14,'Manning''s Flow'!I$10:J$2010,2,TRUE) -> 110.20062 | P14: =ABS(F14-O14) -> 61.792376 | Q14: =P14^2 -> 3818.2977 | R14: =100*ABS(P14/O14) -> 56.072619
A15: 43870.59 | B15: 43870 | C15: 0.59027778 | D15: 1.017 | E15: 3.6 | F15: 153.78 | G15: 142.6498 | I15: =26.666*(D15^2.1619) -> 27.655725 | J15: =ABS(I15-F15) -> 126.12428 | K15: =J15^2 -> 15907.333 | L15: =100*ABS(J15/I15) -> 456.05124 | O15: =VLOOKUP(D15,'Manning''s Flow'!I$10:J$2010,2,TRUE) -> 90.885907 | P15: =ABS(F15-O15) -> 62.894093 | Q15: =P15^2 -> 3955.667 | R15: =100*ABS(P15/O15) -> 69.201151
... A2444: 44069.885 | B2444: 44069 | C2444: 0.88541667 | D2444: 0.113 | E2444: 0.01 | F2444: 0.046 | G2444: 0.0115 | I2444: =26.666*(D2444^2.1619) -> 0.23922588 | J2444: =ABS(I2444-F2444) -> 0.19322588 | K2444: =J2444^2 -> 0.037336241 | L2444: =100*ABS(J2444/I2444) -> 80.771311 | O2444: =VLOOKUP(D2444,'Manning''s Flow'!I$10:J$2010,2,TRUE) -> 2.1311924 | P2444: =ABS(F2444-O2444) -> 2.0851924 | Q2444: =P2444^2 -> 4.3480273 | R2444: =100*ABS(P2444/O2444) -> 97.841584

Sheet Manning's Flow
A1: Slope (ft/ft) | B1: 0.011312421 | C1: <- "Calibration" Parameters. Use solver to minimize RMSE by changing channel slope.
A2: Roughness (in) | B2: 0.013
A3: Bottom Width (in) | B3: 12
A4: Top Width (in) | B4: 84
A5: Channel Depth (in) | B5: 21
A6: Sideslope (ft/ft) | B6: =(B4-B3)/2/B5 -> 1.7142857
A7: RMSE (gpm) | B7: ='Filtered Flow Data'!S3 -> 20.496886
A9: Level (ft) | B9: Bottom Width (ft) | C9: Top Width (ft) | D9: Area (ft2) | E9: Wetted Perimeter (ft) | F9: Hydraulic Radius (ft) | G9: Flow (cfs) | I9: Level (in) | J9: Flow (gpm)
A10: 0.001 | B10: =B$3/12 -> 1 | C10: =B10+2*A10*B$6 -> 1.0034286 | D10: =(B10+B$6*A10)*A10 -> 0.0010017143 | E10: =B10+2*A10*SQRT(1+B$6^2) -> 1.0039693 | F10: =D10/E10 -> 0.00099775393 | G10: =(1.49/B$2)*D10*(F10^(2/3))*(B$1^(1/2)) -> 0.00012193083 | I10: 0 | J10: 0
A11: 0.002 | B11: =B$3/12 -> 1 | C11: =B11+2*A11*B$6 -> 1.0068571 | D11: =(B11+B$6*A11)*A11 -> 0.0020068571 | E11: =B11+2*A11*SQRT(1+B$6^2) -> 1.0079385 | F11: =D11/E11 -> 0.0019910511 | G11: =(1.49/B$2)*D11*(F11^(2/3))*(B$1^(1/2)) -> 0.00038719115 | I11: =A10*12 -> 0.012 | J11: =G10*448 -> 0.054625012
A12: 0.003 | B12: =B$3/12 -> 1 | C12: =B12+2*A12*B$6 -> 1.0102857 | D12: =(B12+B$6*A12)*A12 -> 0.0030154286 | E12: =B12+2*A12*SQRT(1+B$6^2) -> 1.0119078 | F12: =D12/E12 -> 0.002979944 | G12: =(1.49/B$2)*D12*(F12^(2/3))*(B$1^(1/2)) -> 0.00076121699 | I12: =A11*12 -> 0.024 | J12: =G11*448 -> 0.17346164
A13: 0.004 | B13: =B$3/12 -> 1 | C13: =B13+2*A13*B$6 -> 1.0137143 | D13: =(B13+B$6*A13)*A13 -> 0.0040274286 | E13: =B13+2*A13*SQRT(1+B$6^2) -> 1.0158771 | F13: =D13/E13 -> 0.0039644841 | G13: =(1.49/B$2)*D13*(F13^(2/3))*(B$1^(1/2)) -> 0.0012298147 | I13: =A12*12 -> 0.036 | J13: =G12*448 -> 0.34102521
A14: 0.005 | B14: =B$3/12 -> 1 | C14: =B14+2*A14*B$6 -> 1.0171429 | D14: =(B14+B$6*A14)*A14 -> 0.0050428571 | E14: =B14+2*A14*SQRT(1+B$6^2) -> 1.0198463 | F14: =D14/E14 -> 0.0049447225 | G14: =(1.49/B$2)*D14*(F14^(2/3))*(B$1^(1/2)) -> 0.0017842621 | I14: =A13*12 -> 0.048 | J14: =G13*448 -> 0.55095697
A15: 0.006 | B15: =B$3/12 -> 1 | C15: =B15+2*A15*B$6 -> 1.0205714 | D15: =(B15+B$6*A15)*A15 -> 0.0060617143 | E15: =B15+2*A15*SQRT(1+B$6^2) -> 1.0238156 | F15: =D15/E15 -> 0.0059207089 | G15: =(1.49/B$2)*D15*(F15^(2/3))*(B$1^(1/2)) -> 0.0024184213 | I15: =A14*12 -> 0.06 | J15: =G14*448 -> 0.79934941
A16: 0.007 | B16: =B$3/12 -> 1 | C16: =B16+2*A16*B$6 -> 1.024 | D16: =(B16+B$6*A16)*A16 -> 0.007084 | E16: =B16+2*A16*SQRT(1+B$6^2) -> 1.0277849 | F16: =D16/E16 -> 0.0068924929 | G16: =(1.49/B$2)*D16*(F16^(2/3))*(B$1^(1/2)) -> 0.0031276403 | I16: =A15*12 -> 0.072 | J16: =G15*448 -> 1.0834528
A17: 0.008 | B17: =B$3/12 -> 1 | C17: =B17+2*A17*B$6 -> 1.0274286 | D17: =(B17+B$6*A17)*A17 -> 0.0081097143 | E17: =B17+2*A17*SQRT(1+B$6^2) -> 1.0317542 | F17: =D17/E17 -> 0.0078601227 | G17: =(1.49/B$2)*D17*(F17^(2/3))*(B$1^(1/2)) -> 0.0039082212 | I17: =A16*12 -> 0.084 | J17: =G16*448 -> 1.4011829
A18: 0.009 | B18: =B$3/12 -> 1 | C18: =B18+2*A18*B$6 -> 1.0308571 | D18: =(B18+B$6*A18)*A18 -> 0.0091388571 | E18: =B18+2*A18*SQRT(1+B$6^2) -> 1.0357234 | F18: =D18/E18 -> 0.0088236463 | G18: =(1.49/B$2)*D18*(F18^(2/3))*(B$1^(1/2)) -> 0.0047571259 | I18: =A17*12 -> 0.096 | J18: =G17*448 -> 1.7508831
A19: 0.01 | B19: =B$3/12 -> 1 | C19: =B19+2*A19*B$6 -> 1.0342857 | D19: =(B19+B$6*A19)*A19 -> 0.010171429 | E19: =B19+2*A19*SQRT(1+B$6^2) -> 1.0396927 | F19: =D19/E19 -> 0.0097831105 | G19: =(1.49/B$2)*D19*(F19^(2/3))*(B$1^(1/2)) -> 0.0056717963 | I19: =A18*12 -> 0.108 | J19: =G18*448 -> 2.1311924
A20: 0.011 | B20: =B$3/12 -> 1 | C20: =B20+2*A20*B$6 -> 1.0377143 | D20: =(B20+B$6*A20)*A20 -> 0.011207429 | E20: =B20+2*A20*SQRT(1+B$6^2) -> 1.043662 | F20: =D20/E20 -> 0.010738562 | G20: =(1.49/B$2)*D20*(F20^(2/3))*(B$1^(1/2)) -> 0.0066500375 | I20: =A19*12 -> 0.12 | J20: =G19*448 -> 2.5409647
A21: 0.012 | B21: =B$3/12 -> 1 | C21: =B21+2*A21*B$6 -> 1.0411429 | D21: =(B21+B$6*A21)*A21 -> 0.012246857 | E21: =B21+2*A21*SQRT(1+B$6^2) -> 1.0476312 | F21: =D21/E21 -> 0.011690046 | G21: =(1.49/B$2)*D21*(F21^(2/3))*(B$1^(1/2)) -> 0.0076899377 | I21: =A20*12 -> 0.132 | J21: =G20*448 -> 2.9792168
A22: 0.013 | B22: =B$3/12 -> 1 | C22: =B22+2*A22*B$6 -> 1.0445714 | D22: =(B22+B$6*A22)*A22 -> 0.013289714 | E22: =B22+2*A22*SQRT(1+B$6^2) -> 1.0516005 | F22: =D22/E22 -> 0.012637607 | G22: =(1.49/B$2)*D22*(F22^(2/3))*(B$1^(1/2)) -> 0.0087898119 | I22: =A21*12 -> 0.144 | J22: =G21*448 -> 3.4450921
... A1760: 1.751 | B1760: =B$3/12 -> 1 | C1760: =B1760+2*A1760*B$6 -> 7.0034286 | D1760: =(B1760+B$6*A1760)*A1760 -> 7.0070017 | E1760: =B1760+2*A1760*SQRT(1+B$6^2) -> 7.9501913 | F1760: =D1760/E1760 -> 0.88136266 | G1760: =(1.49/B$2)*D1760*(F1760^(2/3))*(B$1^(1/2)) -> 78.521638 | I1760: =A1759*12 -> 21 | J1760: =G1759*448 -> 35130.822
I2010: =A2009*12 -> 0 | J2010: =G2009*448 -> 0

Sheet HvF
A1: Level (in) | B1: Flow (gpm)
A2: 0 | B2: 0
A3: 0.012 | B3: 0.054625012
A4: 0.024 | B4: 0.17346164
A5: 0.036 | B5: 0.34102521
A6: 0.048 | B6: 0.55095697
A7: 0.06 | B7: 0.79934941
A8: 0.072 | B8: 1.0834528
A9: 0.084 | B9: 1.4011829
A10: 0.096 | B10: 1.7508831
A11: 0.108 | B11: 2.1311924
A12: 0.12 | B12: 2.5409647
A13: 0.132 | B13: 2.9792168
... A1752: 21 | B1752: 35130.822

Sheet Meta
A1: Level Range (in) | B1: Curve Type | C1: Explanation
A2: Full Range | B2: Manning's | C2: Best fit for full range of observed levels
A4: Explanation of Data Processing for Outfall Rating Curve Development
A5: 1. Raw 950 Data imported. Processed 950 Data does not make a difference for rating curve development due to filtering technique explained in the following step.
A6: 2. Raw 950 Data filtered for negative level, velocity, and flow data. Also filtered for any level, velocity, and flow data pairs containing zero values. Also filtered for duplicate pairs.
A7: 3. Regression Analysis performed for filtered 950 Data. Either a power law equation or even-ordered polynomial was used. Fit of regression analysis evaluated using RMSE between predicted level-flow values and 950 level-flow values.
A8: For most sites, the fit of regressed curves was evaluated visually, bearing in mind how physically realistic the predicted level-flow values were. For example, if a regression equation predicted negative flow or decreasing flow with increasing level, another
A9: equation was used. Also, The equations had to predict zero flow for zero level.
A10: 4. Manning's Equation was also used in the regression analysis to evaluate how 950 data lined up against manning's. For all sites, manning's equation lined up for at least a portion of the curve. For every site, manning's was used on the higher end above the greatest 950 level-flow value pair.
A11: 5. Manning's Equation was calibrated by changing the conveyance slope until a minimum RMSE value was achieved between level-flow value pairs predicted by mannings and those from the 950 data.
A12: 6. The final rating curves for each site are essentially piece-wise functions, most commonly a power law or 4th/6th order polynomial over the range of observed 950 level values, with mannings applied below/above min/max 950 level data. HvF input values are highlighted in green on the tab "Manning's Flow".
